<mujoco model="tidybot scene">
  <include file="tidybot_dishwasher.xml"/>

  <statistic center="0.25 0 0.6" extent="1.0" meansize="0.05"/>

  <visual>
	<quality offsamples="0"/>
	<headlight diffuse="0.6 0.6 0.6" ambient="0.1 0.1 0.1" specular="0 0 0"/>
	<rgba haze="0.15 0.25 0.35 1"/>
	<global azimuth="120" elevation="-20"/>
  </visual>

  <asset>
	<texture type="skybox" builtin="gradient" rgb1="0.3 0.5 0.7" rgb2="0 0 0" width="512" height="3072"/>
	<texture type="2d" name="groundplane" builtin="checker" mark="edge" rgb1="0.2 0.3 0.4" rgb2="0.1 0.2 0.3"
	  markrgb="0.8 0.8 0.8" width="300" height="300"/>
	<material name="groundplane" texture="groundplane" texuniform="true" texrepeat="5 5" reflectance="0.2"/>
	<mesh name="ktc_dishwasher" file="meshes/dishwasher/ktc_dishwasher2.stl" />
	<mesh name="ktc_dishwasher_rack" file="meshes/dishwasher/ktc_dishwasher_rack.stl" />
	<mesh name="ktc_dishwasher_door" file="meshes/dishwasher/ktc_dishwasher_door2.stl" />
	<texture name="T_Metal_bin" type="cube" height="1" width="1" file="textures/metal0.png" />
	<material name="M_Metal_bin" texture="T_Metal_bin" texrepeat="3 3" reflectance="0.7" texuniform="false" />
  </asset>

  <sensor>
    <jointpos name="door" joint="door"/>
  </sensor>

  <worldbody>
	<light pos="0 0 1.5" directional="true"/>
	<geom name="floor" size="0 0 0.05" type="plane" material="groundplane"/>
        <camera name="viewer" pos="0.8 -2.0 1.7" euler="1.0 0.0 0" fovy="42" resolution="640 480"/>
	<body name="interactive_obj" pos="1.5 0 0" quat="0.707 0 0 0.707">
	  <body name="dishwasher" pos="0 0 0" childclass="viz_dishwasher">
		<geom type="mesh" mesh="ktc_dishwasher" euler="1.57 0 0"/>
		<geom type="box" pos="0 0.312 .756" size=".290 .310 .031" class="col"/>  <!-- top -->
		<geom type="box" pos="0 0.312 .055" size=".290 .310 .055" class="col"/> <!-- bottom -->
		<geom type="box" pos="0.26 0.312 .378" size=".031 .310 .378" class="col"/> <!-- left -->
		<geom type="box" pos="-.26 0.312 .378" size=".031 .310 .378" class="col"/> <!-- right -->
		<geom type="box" pos="0 0.071 .378" size=".290 .0710 .378" class="col"/> <!-- back -->

		<body name="top_rack" pos="0 0.375 0.485">
		  <inertial pos="0 0 0" mass="2" diaginertia="1 1 1" />
		  <joint name="top_rack" pos="0 0 0" axis="0 1 0" type="slide" limited="true" range="0 0.274" damping="0.1" frictionloss="0.1" />
		  <geom type="mesh" mesh="ktc_dishwasher_rack" euler="1.57 0 0"/>
		</body>
		<body name="door" pos="0 .622 0.05">
		  <inertial pos="0 0 0" mass="2" diaginertia="1 1 1" />
		  <joint name="door" axis="1 0 0" limited="true" range="-1.5 0" damping="0.1" frictionloss="0.1"/>
		  <geom type="mesh" mesh="ktc_dishwasher_door" mass="2" euler="1.57 0 0"/>
		  <geom type="box" pos="0 0.025 .37" size=".290 .010 .365" rgba=".1 .1 .1 1" />
		  <geom type="capsule" pos="0 0.08 .625" size=".020 .260" euler="0 1.57 0"/>
		  <geom type="capsule" pos="0.26 0.06 .625" size=".020 .020" euler="1.57 0 0"/>
		  <geom type="capsule" pos="-.26 0.06 .625" size=".020 .020" euler="1.57 0 0"/>

		  <geom type="box" pos="0 0.013 .37" size=".290 .0210 .365" class="col"/>
		  <geom type="capsule" pos="0 0.08 .625" size=".020 .260" euler="0 1.57 0" class="col"/>
		  <geom type="capsule" pos="0.26 0.06 .625" size=".020 .020" euler="1.57 0 0" class="col"/>
		  <geom type="capsule" pos="-.26 0.06 .625" size=".020 .020" euler="1.57 0 0" class="col"/>
		</body>
      </body>
      <joint name="interactive_obj_freejoint" type="free"/>
	</body>
  </worldbody>
</mujoco>
